File: source/NIST_Si_.ras
*RAS_DATA_START
*RAS_HEADER_START
*ATMOSPHERE_TEMP_DATAOUT "1.0000000000"
*ATMOSPHERE_TEMP_END "25.0000000000"
*ATMOSPHERE_TEMP_START "25.0000000000"
*ATMOSPHERE_TEMP_UNIT "C"
*ATMOSPHERE_TEMP_UNIT_DISP "0.0000000000"
*DISP_FMT_X "%.2f"
*DISP_FMT_Y "%.0f"
*DISP_FULLSCALE "164430.9817270000"
*DISP_LINE_COLOR "255.0000000000"
*DISP_LINE_STYLE "0.0000000000"
*DISP_LINE_WIDTH "0.2500000000"
*DISP_NOTE "測定データ-1"
*DISP_OFFSET_Y "0.0000000000"
*DISP_PEAKSEARCH_UNIT_Y "cps"
*DISP_RANGE_BOTTOM "0.0000000000"
*DISP_RANGE_LEFT "5.0000000000"
*DISP_RANGE_LOGCUTOFF "0.0100000000"
*DISP_RANGE_RIGHT "150.0000000000"
*DISP_RANGE_TOP "164430.9817270000"
*DISP_SCALE_MODE_Y "0.0000000000"
*DISP_TAB_NAME "2θ/θ"
*DISP_TITLE_Y "強度"
*DISP_UNIT_Y "cps"
*DISP_WINDOW_NAME "MSG_MACROENGINE"
*FILE_COMMENT " "
*FILE_MD5 ""
*FILE_MEMO " "
*FILE_OPERATOR "administrator"
*FILE_PART_ID "MEAS_KHP2_00068"
*FILE_SAMPLE "NIST Si 640c"
*FILE_TYPE "RAS_RAW"
*FILE_USERGROUP "システムマネージャ"
*FILE_VERSION "1.0000000000"
*HW_ATTACHMENT_ID "ATT0172"
*HW_ATTACHMENT_NAME "多目的高温|Multi-Temparature"
*HW_COUNTER_ID-0 "CUT0041"
*HW_COUNTER_ID-1 "CUT0020"
*HW_COUNTER_ID-2 "CUT0020"
*HW_COUNTER_ID-3 "CSL0021"
*HW_COUNTER_ID-4 "CMC0021"
*HW_COUNTER_NAME-0 "D/teX Ultra 250|D/teX Ultra 250"
*HW_COUNTER_NAME-1 "None|None"
*HW_COUNTER_NAME-2 "None|None"
*HW_COUNTER_NAME-3 "BBM|BBM"
*HW_COUNTER_NAME-4 "検出器モノクロメータ|Detector monochromator"
*HW_COUNTER_SELECT_NAME "D/teX Ultra 250|D/teX Ultra 250"
*HW_GONIOMETER_ID "GON0023"
*HW_GONIOMETER_NAME "SmartLab|SmartLab"
*HW_GONIOMETER_RADIUS-0 "90.0"
*HW_GONIOMETER_RADIUS-1 "114.0"
*HW_GONIOMETER_RADIUS-2 "190.0"
*HW_GONIOMETER_RADIUS-3 "300.0"
*HW_GONIOMETER_RADIUS-4 "187.0"
*HW_GONIOMETER_RADIUS-5 "300.0"
*HW_GONIOMETER_RADIUS-6 "113.0"
*HW_GONIOMETER_RADIUS-7 "331.0"
*HW_I_OPT_ID-0 "CBO0021"
*HW_I_OPT_ID-1 "ICR0023"
*HW_I_OPT_ID-2 "ISL0021"
*HW_I_OPT_ID-3 "ISO0021"
*HW_I_OPT_ID-4 "IAD0021"
*HW_I_OPT_ID-5 "IPR0002"
*HW_I_OPT_NAME-0 "CBOユニット|CBO unit"
*HW_I_OPT_NAME-1 "標準入射光学ユニット|Standard incident optical unit"
*HW_I_OPT_NAME-2 "標準入射スリットボックス|Standard incident slit box"
*HW_I_OPT_NAME-3 "入射平行スリット|Incident parallel slit"
*HW_I_OPT_NAME-4 "長手制限スリット|Length limiting slit"
*HW_I_OPT_NAME-5 "Ka1|Ka1"
*HW_R_ATTENUATER_AUTOMODE "0"
*HW_R_OPT_ID-0 "RSS0021"
*HW_R_OPT_ID-1 "RCR0023"
*HW_R_OPT_ID-2 "RSO0021"
*HW_R_OPT_ID-3 "RRS0021"
*HW_R_OPT_ID-4 "ATN0021"
*HW_R_OPT_ID-5 "RFL0021"
*HW_R_OPT_ID-6 "RAD0021"
*HW_R_OPT_NAME-0 "標準受光スリットボックス1|Standard receiving slit box # 1"
*HW_R_OPT_NAME-1 "標準受光光学ユニット1|Standard receiving unit # 1"
*HW_R_OPT_NAME-2 "標準受光光学ユニット2|Standard receiving optical unit # 2"
*HW_R_OPT_NAME-3 "標準受光スリットボックス2|Standard receiving slit box # 2"
*HW_R_OPT_NAME-4 "標準アッテネータ|Standard Attenuator"
*HW_R_OPT_NAME-5 "Cu Kβ|Cu K-beta"
*HW_R_OPT_NAME-6 "調整用受光スリット|Alignment receiving slit"
*HW_SAMPLE_HOLDER_ID "SMP0025"
*HW_SAMPLE_HOLDER_NAME "Zステージ単独|Z stage only"
*HW_XG_CURRENT_MAX "200"
*HW_XG_CURRENT_MIN "10"
*HW_XG_CURRENT_RESOLUTION "1"
*HW_XG_CURRENT_UNIT "mA"
*HW_XG_FOCUS "0.4mm x 8mm"
*HW_XG_FOCUS_TYPE "Fine"
*HW_XG_ID ""
*HW_XG_NAME "9kW 開放管(45kV 200mA ID:1700)|9kW Rotating anode(45kV 200mA ID:1700)"
*HW_XG_TARGET_ATOMIC_NUMBER "29.0000000000"
*HW_XG_TARGET_NAME "Cu"
*HW_XG_TYPE "Rota"
*HW_XG_VOLTAGE_MAX "45"
*HW_XG_VOLTAGE_MIN "20"
*HW_XG_VOLTAGE_RESOLUTION "1"
*HW_XG_VOLTAGE_UNIT "kV"
*HW_XG_WATT_MAX "9.00"
*HW_XG_WATT_UNIT "kW"
*HW_XG_WAVE_LENGTH_ALPHA1 "1.540593"
*HW_XG_WAVE_LENGTH_ALPHA2 "1.544414"
*HW_XG_WAVE_LENGTH_BETA "1.392250"
*MEAS_COND_AXIS_NAME-0 "2θ/θ"
*MEAS_COND_AXIS_NAME-1 "2θ"
*MEAS_COND_AXIS_NAME-2 "ω"
*MEAS_COND_AXIS_NAME-3 "Z"
*MEAS_COND_AXIS_NAME-4 "2θ/ω"
*MEAS_COND_AXIS_NAME-5 "θs"
*MEAS_COND_AXIS_NAME-6 "θd"
*MEAS_COND_AXIS_NAME-7 "Ts"
*MEAS_COND_AXIS_NAME-8 "CBO選択スリット"
*MEAS_COND_AXIS_NAME-9 "M"
*MEAS_COND_AXIS_NAME-10 "入射平行スリット"
*MEAS_COND_AXIS_NAME-11 "入射スリット"
*MEAS_COND_AXIS_NAME-12 ""
*MEAS_COND_AXIS_NAME-13 "Zs"
*MEAS_COND_AXIS_NAME-14 "入射光学素子"
*MEAS_COND_AXIS_NAME-15 "長手制限スリット"
*MEAS_COND_AXIS_NAME-16 "センタースリット"
*MEAS_COND_AXIS_NAME-17 "フィルター"
*MEAS_COND_AXIS_NAME-18 "受光スリット1"
*MEAS_COND_AXIS_NAME-19 "受光スリット2"
*MEAS_COND_AXIS_NAME-20 "受光光学素子"
*MEAS_COND_AXIS_NAME-21 "受光平行スリット"
*MEAS_COND_AXIS_NAME-22 "調整用受光スリット"
*MEAS_COND_AXIS_NAME-23 ""
*MEAS_COND_AXIS_NAME-24 ""
*MEAS_COND_AXIS_NAME-25 "Zd"
*MEAS_COND_AXIS_NAME-26 "アッテネータ"
*MEAS_COND_AXIS_NAME-27 "検出器モノクロメータ"
*MEAS_COND_AXIS_NAME-28 "モノクロメータスリット"
*MEAS_COND_AXIS_NAME-29 "プライマリビーム"
*MEAS_COND_AXIS_NAME-30 "Ma"
*MEAS_COND_AXIS_NAME-31 "PHA"
*MEAS_COND_AXIS_NAME-32 "Temperature"
*MEAS_COND_AXIS_NAME_INTERNAL-0 "TwoThetaTheta"
*MEAS_COND_AXIS_NAME_INTERNAL-1 "TwoTheta"
*MEAS_COND_AXIS_NAME_INTERNAL-2 "Omega"
*MEAS_COND_AXIS_NAME_INTERNAL-3 "Z"
*MEAS_COND_AXIS_NAME_INTERNAL-4 "TwoThetaOmega"
*MEAS_COND_AXIS_NAME_INTERNAL-5 "ThetaS"
*MEAS_COND_AXIS_NAME_INTERNAL-6 "ThetaD"
*MEAS_COND_AXIS_NAME_INTERNAL-7 "Ts"
*MEAS_COND_AXIS_NAME_INTERNAL-8 "CBO"
*MEAS_COND_AXIS_NAME_INTERNAL-9 "CBO-M"
*MEAS_COND_AXIS_NAME_INTERNAL-10 "IncidentSollerSlit"
*MEAS_COND_AXIS_NAME_INTERNAL-11 "IncidentSlitBox"
*MEAS_COND_AXIS_NAME_INTERNAL-12 "IncidentSlitBox-_Axis"
*MEAS_COND_AXIS_NAME_INTERNAL-13 "Zs"
*MEAS_COND_AXIS_NAME_INTERNAL-14 "IncidentMonochromator"
*MEAS_COND_AXIS_NAME_INTERNAL-15 "IncidentAxdSlit"
*MEAS_COND_AXIS_NAME_INTERNAL-16 "CenterSlit"
*MEAS_COND_AXIS_NAME_INTERNAL-17 "Filter"
*MEAS_COND_AXIS_NAME_INTERNAL-18 "ReceivingSlitBox1"
*MEAS_COND_AXIS_NAME_INTERNAL-19 "ReceivingSlitBox2"
*MEAS_COND_AXIS_NAME_INTERNAL-20 "ReceivingOptics"
*MEAS_COND_AXIS_NAME_INTERNAL-21 "ReceivingSollerSlit"
*MEAS_COND_AXIS_NAME_INTERNAL-22 "ReceivingAxdSlit"
*MEAS_COND_AXIS_NAME_INTERNAL-23 "ReceivingSlitBox1-_Axis"
*MEAS_COND_AXIS_NAME_INTERNAL-24 "ReceivingSlitBox2-_Axis"
*MEAS_COND_AXIS_NAME_INTERNAL-25 "ReceivingSlitBox2-Zd"
*MEAS_COND_AXIS_NAME_INTERNAL-26 "Attenuator"
*MEAS_COND_AXIS_NAME_INTERNAL-27 "CounterMonochromator"
*MEAS_COND_AXIS_NAME_INTERNAL-28 "CounterSlit"
*MEAS_COND_AXIS_NAME_INTERNAL-29 "IncidentPrimary"
*MEAS_COND_AXIS_NAME_INTERNAL-30 "IncidentPrimary-Ma"
*MEAS_COND_AXIS_NAME_INTERNAL-31 "PHA"
*MEAS_COND_AXIS_NAME_INTERNAL-32 "Temperature"
*MEAS_COND_AXIS_NAME_MAGICNO-0 "83951616.0000000000"
*MEAS_COND_AXIS_NAME_MAGICNO-1 "268632064.0000000000"
*MEAS_COND_AXIS_NAME_MAGICNO-2 "268500992.0000000000"
*MEAS_COND_AXIS_NAME_MAGICNO-3 "285278208.0000000000"
*MEAS_COND_AXIS_NAME_MAGICNO-4 "83951616.0000000000"
*MEAS_COND_AXIS_NAME_MAGICNO-5 "131072.0000000000"
*MEAS_COND_AXIS_NAME_MAGICNO-6 "131072.0000000000"
*MEAS_COND_AXIS_NAME_MAGICNO-7 "318898176.0000000000"
*MEAS_COND_AXIS_NAME_MAGICNO-8 "20971521.0000000000"
*MEAS_COND_AXIS_NAME_MAGICNO-9 "285343744.0000000000"
*MEAS_COND_AXIS_NAME_MAGICNO-10 "20971521.0000000000"
*MEAS_COND_AXIS_NAME_MAGICNO-11 "22020097.0000000000"
*MEAS_COND_AXIS_NAME_MAGICNO-12 "25165824.0000000000"
*MEAS_COND_AXIS_NAME_MAGICNO-13 "318898176.0000000000"
*MEAS_COND_AXIS_NAME_MAGICNO-14 "1.0000000000"
*MEAS_COND_AXIS_NAME_MAGICNO-15 "20971521.0000000000"
*MEAS_COND_AXIS_NAME_MAGICNO-16 "20971521.0000000000"
*MEAS_COND_AXIS_NAME_MAGICNO-17 "20971521.0000000000"
*MEAS_COND_AXIS_NAME_MAGICNO-18 "23068673.0000000000"
*MEAS_COND_AXIS_NAME_MAGICNO-19 "23068673.0000000000"
*MEAS_COND_AXIS_NAME_MAGICNO-20 "20971521.0000000000"
*MEAS_COND_AXIS_NAME_MAGICNO-21 "20971521.0000000000"
*MEAS_COND_AXIS_NAME_MAGICNO-22 "20971521.0000000000"
*MEAS_COND_AXIS_NAME_MAGICNO-23 "25165824.0000000000"
*MEAS_COND_AXIS_NAME_MAGICNO-24 "25165824.0000000000"
*MEAS_COND_AXIS_NAME_MAGICNO-25 "285343744.0000000000"
*MEAS_COND_AXIS_NAME_MAGICNO-26 "17301505.0000000000"
*MEAS_COND_AXIS_NAME_MAGICNO-27 "20971521.0000000000"
*MEAS_COND_AXIS_NAME_MAGICNO-28 "20971521.0000000000"
*MEAS_COND_AXIS_NAME_MAGICNO-29 "20971521.0000000000"
*MEAS_COND_AXIS_NAME_MAGICNO-30 "285343744.0000000000"
*MEAS_COND_AXIS_NAME_MAGICNO-31 "0.0000000000"
*MEAS_COND_AXIS_NAME_MAGICNO-32 "0.0000000000"
*MEAS_COND_AXIS_OFFSET-0 "-"
*MEAS_COND_AXIS_OFFSET-1 "0.3314000000"
*MEAS_COND_AXIS_OFFSET-2 "2.8273000000"
*MEAS_COND_AXIS_OFFSET-3 "-"
*MEAS_COND_AXIS_OFFSET-4 "-"
*MEAS_COND_AXIS_OFFSET-5 "2.8273000000"
*MEAS_COND_AXIS_OFFSET-6 "-2.4959000000"
*MEAS_COND_AXIS_OFFSET-7 "-"
*MEAS_COND_AXIS_OFFSET-8 "-"
*MEAS_COND_AXIS_OFFSET-9 "-"
*MEAS_COND_AXIS_OFFSET-10 "-"
*MEAS_COND_AXIS_OFFSET-11 "-"
*MEAS_COND_AXIS_OFFSET-12 "-"
*MEAS_COND_AXIS_OFFSET-13 "-"
*MEAS_COND_AXIS_OFFSET-14 "-"
*MEAS_COND_AXIS_OFFSET-15 "-"
*MEAS_COND_AXIS_OFFSET-16 "-"
*MEAS_COND_AXIS_OFFSET-17 "-"
*MEAS_COND_AXIS_OFFSET-18 "-"
*MEAS_COND_AXIS_OFFSET-19 "-"
*MEAS_COND_AXIS_OFFSET-20 "-"
*MEAS_COND_AXIS_OFFSET-21 "-"
*MEAS_COND_AXIS_OFFSET-22 "-"
*MEAS_COND_AXIS_OFFSET-23 "-"
*MEAS_COND_AXIS_OFFSET-24 "-"
*MEAS_COND_AXIS_OFFSET-25 "-"
*MEAS_COND_AXIS_OFFSET-26 "-"
*MEAS_COND_AXIS_OFFSET-27 "-"
*MEAS_COND_AXIS_OFFSET-28 "-"
*MEAS_COND_AXIS_OFFSET-29 "-"
*MEAS_COND_AXIS_OFFSET-30 "-"
*MEAS_COND_AXIS_OFFSET-31 "-"
*MEAS_COND_AXIS_OFFSET-32 "0.0000000000"
*MEAS_COND_AXIS_POSITION-0 "0.0000000000"
*MEAS_COND_AXIS_POSITION-1 "0.0000000000"
*MEAS_COND_AXIS_POSITION-2 "0.0000000000"
*MEAS_COND_AXIS_POSITION-3 "0.4951400000"
*MEAS_COND_AXIS_POSITION-4 "0.0000000000"
*MEAS_COND_AXIS_POSITION-5 "0.0000000000"
*MEAS_COND_AXIS_POSITION-6 "0.0000000000"
*MEAS_COND_AXIS_POSITION-7 "-0.8201200000"
*MEAS_COND_AXIS_POSITION-8 "BB"
*MEAS_COND_AXIS_POSITION-9 "0.0000000000"
*MEAS_COND_AXIS_POSITION-10 "Soller_slit_5.0deg"
*MEAS_COND_AXIS_POSITION-11 "2/3deg"
*MEAS_COND_AXIS_POSITION-12 "2.2088000000"
*MEAS_COND_AXIS_POSITION-13 "-0.7650000000"
*MEAS_COND_AXIS_POSITION-14 "0.0000000000"
*MEAS_COND_AXIS_POSITION-15 "5.0mm"
*MEAS_COND_AXIS_POSITION-16 "None"
*MEAS_COND_AXIS_POSITION-17 "None"
*MEAS_COND_AXIS_POSITION-18 "18.000mm"
*MEAS_COND_AXIS_POSITION-19 "18.000mm"
*MEAS_COND_AXIS_POSITION-20 "No_unit"
*MEAS_COND_AXIS_POSITION-21 "Soller_slit_5.0deg"
*MEAS_COND_AXIS_POSITION-22 "None"
*MEAS_COND_AXIS_POSITION-23 "18.0000000000"
*MEAS_COND_AXIS_POSITION-24 "18.0000000000"
*MEAS_COND_AXIS_POSITION-25 "0.1762500000"
*MEAS_COND_AXIS_POSITION-26 "Open"
*MEAS_COND_AXIS_POSITION-27 "None"
*MEAS_COND_AXIS_POSITION-28 "None"
*MEAS_COND_AXIS_POSITION-29 "Johansson(Ka1)"
*MEAS_COND_AXIS_POSITION-30 "0.0000000000"
*MEAS_COND_AXIS_POSITION-31 "38.0000000000"
*MEAS_COND_AXIS_POSITION-32 "25.0000000000"
*MEAS_COND_AXIS_UNIT-0 "deg"
*MEAS_COND_AXIS_UNIT-1 "deg"
*MEAS_COND_AXIS_UNIT-2 "deg"
*MEAS_COND_AXIS_UNIT-3 "mm"
*MEAS_COND_AXIS_UNIT-4 "deg"
*MEAS_COND_AXIS_UNIT-5 "deg"
*MEAS_COND_AXIS_UNIT-6 "deg"
*MEAS_COND_AXIS_UNIT-7 "mm"
*MEAS_COND_AXIS_UNIT-8 ""
*MEAS_COND_AXIS_UNIT-9 "pulse"
*MEAS_COND_AXIS_UNIT-10 ""
*MEAS_COND_AXIS_UNIT-11 ""
*MEAS_COND_AXIS_UNIT-12 "mm"
*MEAS_COND_AXIS_UNIT-13 "mm"
*MEAS_COND_AXIS_UNIT-14 ""
*MEAS_COND_AXIS_UNIT-15 ""
*MEAS_COND_AXIS_UNIT-16 ""
*MEAS_COND_AXIS_UNIT-17 ""
*MEAS_COND_AXIS_UNIT-18 ""
*MEAS_COND_AXIS_UNIT-19 ""
*MEAS_COND_AXIS_UNIT-20 ""
*MEAS_COND_AXIS_UNIT-21 ""
*MEAS_COND_AXIS_UNIT-22 ""
*MEAS_COND_AXIS_UNIT-23 "mm"
*MEAS_COND_AXIS_UNIT-24 "mm"
*MEAS_COND_AXIS_UNIT-25 "mm"
*MEAS_COND_AXIS_UNIT-26 ""
*MEAS_COND_AXIS_UNIT-27 ""
*MEAS_COND_AXIS_UNIT-28 ""
*MEAS_COND_AXIS_UNIT-29 ""
*MEAS_COND_AXIS_UNIT-30 "pulse"
*MEAS_COND_AXIS_UNIT-31 "div"
*MEAS_COND_AXIS_UNIT-32 "C"
*MEAS_COND_COUNTER_CNTLOSS_CORR "0.0000000000"
*MEAS_COND_COUNTER_PHABASE "38.0000000000"
*MEAS_COND_COUNTER_PHAWINDOW "15.0000000000"
*MEAS_COND_COUNTER_PHA_UNIT "div"
*MEAS_COND_COUNTER_TAUDIFF "0.0000000000"
*MEAS_COND_COUNTER_TAUINT "0.0000000000"
*MEAS_COND_IRRADIATION_MODE "OFF"
*MEAS_COND_IRRADIATION_WIDTH ""
*MEAS_COND_OPT_ATTR "集中法"
*MEAS_COND_OPT_NAME "@集中法"
*MEAS_COND_UNSYMMETRIC_MODE "OFF"
*MEAS_COND_XG_CURRENT "200.0000000000"
*MEAS_COND_XG_VOLTAGE "45.0000000000"
*MEAS_COND_XG_WAVE_TYPE "Ka1"
*MEAS_DATA_COUNT "7251.0000000000"
*MEAS_SCAN_AXIS_X "2θ/θ"
*MEAS_SCAN_AXIS_X_INTERNAL "TwoThetaTheta"
*MEAS_SCAN_END_TIME "12/06/18 20:19:24"
*MEAS_SCAN_MODE "CONTINUOUS"
*MEAS_SCAN_MONITOR "0"
*MEAS_SCAN_RESOLUTION_X "0.0002"
*MEAS_SCAN_SPEED "5.098477"
*MEAS_SCAN_SPEED_UNIT "deg/min"
*MEAS_SCAN_SPEED_USER "5.0"
*MEAS_SCAN_START "5.0000000000"
*MEAS_SCAN_START_TIME "12/06/18 19:49:16"
*MEAS_SCAN_STEP "0.0200000000"
*MEAS_SCAN_STOP "150.0000000000"
*MEAS_SCAN_UNIT_X "deg"
*MEAS_SCAN_UNIT_Y "counts"
*RAS_HEADER_END
*RAS_INT_START
5.0000 2297.0000 1.0000
5.1000 2032.0000 1.0000
5.2000 1947.0000 1.0000
5.3000 1938.0000 1.0000
5.4000 1905.0000 1.0000
5.5000 1820.0000 1.0000
5.6000 1800.0000 1.0000
5.7000 1788.0000 1.0000
5.8000 1788.0000 1.0000
5.9000 1750.0000 1.0000
6.0000 1736.0000 1.0000
6.1000 1729.0000 1.0000
6.2000 1696.0000 1.0000
6.3000 1699.0000 1.0000
6.4000 1736.0000 1.0000
6.5000 1718.0000 1.0000
6.6000 1767.0000 1.0000
6.7000 1647.0000 1.0000
6.8000 1707.0000 1.0000
6.9000 1652.0000 1.0000
7.0000 1637.0000 1.0000
7.1000 1534.0000 1.0000
7.2000 1562.0000 1.0000
7.3000 1427.0000 1.0000
7.4000 1367.0000 1.0000
7.5000 1403.0000 1.0000
7.6000 1406.0000 1.0000
7.7000 1352.0000 1.0000
7.8000 1263.0000 1.0000
7.9000 1235.0000 1.0000
8.0000 1188.0000 1.0000
8.1000 1151.0000 1.0000
8.2000 1219.0000 1.0000
8.3000 1211.0000 1.0000
8.4000 1155.0000 1.0000
8.5000 1116.0000 1.0000
8.6000 1131.0000 1.0000
8.7000 1129.0000 1.0000
8.8000 1158.0000 1.0000
8.9000 1090.0000 1.0000
9.0000 1084.0000 1.0000
9.1000 1075.0000 1.0000
9.2000 1111.0000 1.0000
9.3000 1106.0000 1.0000
9.4000 953.0000 1.0000
9.5000 1095.0000 1.0000
9.6000 1099.0000 1.0000
9.7000 1039.0000 1.0000
9.8000 1029.0000 1.0000
9.9000 1036.0000 1.0000
10.0000 941.0000 1.0000
10.1000 1020.0000 1.0000
10.2000 964.0000 1.0000
10.3000 945.0000 1.0000
10.4000 947.0000 1.0000
10.5000 964.0000 1.0000
10.6000 982.0000 1.0000
10.7000 983.0000 1.0000
10.8000 941.0000 1.0000
10.9000 941.0000 1.0000
11.0000 941.0000 1.0000
11.1000 930.0000 1.0000
11.2000 931.0000 1.0000
11.3000 903.0000 1.0000
11.4000 943.0000 1.0000
11.5000 981.0000 1.0000
11.6000 927.0000 1.0000
11.7000 939.0000 1.0000
11.8000 944.0000 1.0000
11.9000 867.0000 1.0000
12.0000 882.0000 1.0000
12.1000 823.0000 1.0000
12.2000 919.0000 1.0000
12.3000 1027.0000 1.0000
12.4000 868.0000 1.0000
12.5000 867.0000 1.0000
12.6000 835.0000 1.0000
12.7000 841.0000 1.0000
12.8000 821.0000 1.0000
12.9000 800.0000 1.0000
13.0000 850.0000 1.0000
13.1000 815.0000 1.0000
13.2000 818.0000 1.0000
13.3000 829.0000 1.0000
13.4000 843.0000 1.0000
13.5000 765.0000 1.0000
13.6000 889.0000 1.0000
13.7000 836.0000 1.0000
13.8000 850.0000 1.0000
13.9000 814.0000 1.0000
14.0000 805.0000 1.0000
14.1000 791.0000 1.0000
14.2000 745.0000 1.0000
14.3000 716.0000 1.0000
14.4000 785.0000 1.0000
14.5000 759.0000 1.0000
14.6000 747.0000 1.0000
14.7000 767.0000 1.0000
14.8000 756.0000 1.0000
14.9000 723.0000 1.0000
15.0000 808.0000 1.0000
15.1000 733.0000 1.0000
15.2000 768.0000 1.0000
15.3000 739.0000 1.0000
15.4000 790.0000 1.0000
15.5000 753.0000 1.0000
15.6000 721.0000 1.0000
15.7000 737.0000 1.0000
15.8000 756.0000 1.0000
15.9000 705.0000 1.0000
16.0000 698.0000 1.0000
16.1000 713.0000 1.0000
16.2000 703.0000 1.0000
16.3000 718.0000 1.0000
16.4000 738.0000 1.0000
16.5000 698.0000 1.0000
16.6000 722.0000 1.0000
16.7000 710.0000 1.0000
16.8000 712.0000 1.0000
16.9000 653.0000 1.0000
17.0000 710.0000 1.0000
17.1000 701.0000 1.0000
17.2000 674.0000 1.0000
17.3000 672.0000 1.0000
17.4000 668.0000 1.0000
17.5000 651.0000 1.0000
17.6000 671.0000 1.0000
17.7000 673.0000 1.0000
17.8000 669.0000 1.0000
17.9000 661.0000 1.0000
18.0000 671.0000 1.0000
18.1000 649.0000 1.0000
18.2000 669.0000 1.0000
18.3000 663.0000 1.0000
18.4000 642.0000 1.0000
18.5000 620.0000 1.0000
18.6000 648.0000 1.0000
18.7000 655.0000 1.0000
18.8000 600.0000 1.0000
18.9000 608.0000 1.0000
19.0000 593.0000 1.0000
19.1000 575.0000 1.0000
19.2000 580.0000 1.0000
19.3000 612.0000 1.0000
19.4000 611.0000 1.0000
19.5000 601.0000 1.0000
19.6000 605.0000 1.0000
19.7000 578.0000 1.0000
19.8000 566.0000 1.0000
19.9000 568.0000 1.0000
20.0000 580.0000 1.0000
20.1000 591.0000 1.0000
20.2000 573.0000 1.0000
20.3000 594.0000 1.0000
20.4000 592.0000 1.0000
20.5000 550.0000 1.0000
20.6000 563.0000 1.0000
20.7000 573.0000 1.0000
20.8000 526.0000 1.0000
20.9000 554.0000 1.0000
21.0000 532.0000 1.0000
21.1000 542.0000 1.0000
21.2000 547.0000 1.0000
21.3000 565.0000 1.0000
21.4000 572.0000 1.0000
21.5000 550.0000 1.0000
21.6000 516.0000 1.0000
21.7000 555.0000 1.0000
21.8000 501.0000 1.0000
21.9000 494.0000 1.0000
22.0000 489.0000 1.0000
22.1000 490.0000 1.0000
22.2000 505.0000 1.0000
22.3000 516.0000 1.0000
22.4000 484.0000 1.0000
22.5000 499.0000 1.0000
22.6000 483.0000 1.0000
22.7000 502.0000 1.0000
22.8000 489.0000 1.0000
22.9000 442.0000 1.0000
23.0000 476.0000 1.0000
23.1000 472.0000 1.0000
23.2000 537.0000 1.0000
23.3000 469.0000 1.0000
23.4000 481.0000 1.0000
23.5000 445.0000 1.0000
23.6000 455.0000 1.0000
23.7000 420.0000 1.0000
23.8000 458.0000 1.0000
23.9000 444.0000 1.0000
24.0000 403.0000 1.0000
24.1000 409.0000 1.0000
24.2000 417.0000 1.0000
24.3000 457.0000 1.0000
24.4000 478.0000 1.0000
24.5000 417.0000 1.0000
24.6000 406.0000 1.0000
24.7000 595.0000 1.0000
24.8000 823.0000 1.0000
24.9000 501.0000 1.0000
25.0000 422.0000 1.0000
25.1000 422.0000 1.0000
25.2000 416.0000 1.0000
25.3000 421.0000 1.0000
25.4000 410.0000 1.0000
25.5000 364.0000 1.0000
25.6000 419.0000 1.0000
25.7000 387.0000 1.0000
25.8000 410.0000 1.0000
25.9000 407.0000 1.0000
26.0000 403.0000 1.0000
26.1000 461.0000 1.0000
26.2000 563.0000 1.0000
26.3000 401.0000 1.0000
26.4000 428.0000 1.0000
26.5000 608.0000 1.0000
26.6000 596.0000 1.0000
26.7000 446.0000 1.0000
26.8000 375.0000 1.0000
26.9000 360.0000 1.0000
27.0000 362.0000 1.0000
27.1000 317.0000 1.0000
27.2000 374.0000 1.0000
27.3000 453.0000 1.0000
27.4000 418.0000 1.0000
27.5000 447.0000 1.0000
27.6000 383.0000 1.0000
27.7000 331.0000 1.0000
27.8000 329.0000 1.0000
27.9000 439.0000 1.0000
28.0000 429.0000 1.0000
28.1000 697.0000 1.0000
28.2000 2799.0000 1.0000
28.3000 13578.0000 1.0000
28.4000 27722.0000 1.0000
28.5000 967.0000 1.0000
28.6000 496.0000 1.0000
28.7000 406.0000 1.0000
28.8000 387.0000 1.0000
28.9000 316.0000 1.0000
29.0000 352.0000 1.0000
29.1000 321.0000 1.0000
29.2000 320.0000 1.0000
29.3000 367.0000 1.0000
29.4000 335.0000 1.0000
29.5000 292.0000 1.0000
29.6000 268.0000 1.0000
29.7000 277.0000 1.0000
29.8000 290.0000 1.0000
29.9000 266.0000 1.0000
30.0000 268.0000 1.0000
30.1000 298.0000 1.0000
30.2000 254.0000 1.0000
30.3000 262.0000 1.0000
30.4000 247.0000 1.0000
30.5000 265.0000 1.0000
30.6000 228.0000 1.0000
30.7000 240.0000 1.0000
30.8000 261.0000 1.0000
30.9000 257.0000 1.0000
31.0000 257.0000 1.0000
31.1000 273.0000 1.0000
31.2000 245.0000 1.0000
31.3000 259.0000 1.0000
31.4000 240.0000 1.0000
31.5000 239.0000 1.0000
31.6000 249.0000 1.0000
31.7000 219.0000 1.0000
31.8000 208.0000 1.0000
31.9000 225.0000 1.0000
32.0000 235.0000 1.0000
32.1000 208.0000 1.0000
32.2000 241.0000 1.0000
32.3000 223.0000 1.0000
32.4000 204.0000 1.0000
32.5000 226.0000 1.0000
32.6000 198.0000 1.0000
32.7000 246.0000 1.0000
32.8000 213.0000 1.0000
32.9000 228.0000 1.0000
33.0000 226.0000 1.0000
33.1000 195.0000 1.0000
33.2000 225.0000 1.0000
33.3000 212.0000 1.0000
33.4000 201.0000 1.0000
33.5000 199.0000 1.0000
33.6000 189.0000 1.0000
33.7000 172.0000 1.0000
33.8000 195.0000 1.0000
33.9000 196.0000 1.0000
34.0000 172.0000 1.0000
34.1000 182.0000 1.0000
34.2000 178.0000 1.0000
34.3000 199.0000 1.0000
34.4000 180.0000 1.0000
34.5000 179.0000 1.0000
34.6000 185.0000 1.0000
34.7000 197.0000 1.0000
34.8000 156.0000 1.0000
34.9000 178.0000 1.0000
35.0000 158.0000 1.0000
35.1000 166.0000 1.0000
35.2000 168.0000 1.0000
35.3000 177.0000 1.0000
35.4000 141.0000 1.0000
35.5000 161.0000 1.0000
35.6000 152.0000 1.0000
35.7000 141.0000 1.0000
35.8000 149.0000 1.0000
35.9000 154.0000 1.0000
36.0000 141.0000 1.0000
36.1000 160.0000 1.0000
36.2000 148.0000 1.0000
36.3000 168.0000 1.0000
36.4000 143.0000 1.0000
36.5000 162.0000 1.0000
36.6000 130.0000 1.0000
36.7000 140.0000 1.0000
36.8000 143.0000 1.0000
36.9000 136.0000 1.0000
37.0000 140.0000 1.0000
37.1000 133.0000 1.0000
37.2000 125.0000 1.0000
37.3000 131.0000 1.0000
37.4000 116.0000 1.0000
37.5000 142.0000 1.0000
37.6000 125.0000 1.0000
37.7000 131.0000 1.0000
37.8000 123.0000 1.0000
37.9000 139.0000 1.0000
38.0000 113.0000 1.0000
38.1000 120.0000 1.0000
38.2000 121.0000 1.0000
38.3000 129.0000 1.0000
38.4000 116.0000 1.0000
38.5000 111.0000 1.0000
38.6000 131.0000 1.0000
38.7000 126.0000 1.0000
38.8000 132.0000 1.0000
38.9000 128.0000 1.0000
39.0000 111.0000 1.0000
39.1000 120.0000 1.0000
39.2000 99.0000 1.0000
39.3000 106.0000 1.0000
39.4000 108.0000 1.0000
39.5000 100.0000 1.0000
39.6000 123.0000 1.0000
39.7000 130.0000 1.0000
39.8000 109.0000 1.0000
39.9000 116.0000 1.0000
40.0000 110.0000 1.0000
40.1000 112.0000 1.0000
40.2000 118.0000 1.0000
40.3000 116.0000 1.0000
40.4000 116.0000 1.0000
40.5000 132.0000 1.0000
40.6000 110.0000 1.0000
40.7000 101.0000 1.0000
40.8000 117.0000 1.0000
40.9000 116.0000 1.0000
41.0000 114.0000 1.0000
41.1000 118.0000 1.0000
41.2000 107.0000 1.0000
41.3000 99.0000 1.0000
41.4000 108.0000 1.0000
41.5000 85.0000 1.0000
41.6000 99.0000 1.0000
41.7000 107.0000 1.0000
41.8000 85.0000 1.0000
41.9000 93.0000 1.0000
42.0000 103.0000 1.0000
42.1000 97.0000 1.0000
42.2000 87.0000 1.0000
42.3000 102.0000 1.0000
42.4000 85.0000 1.0000
42.5000 87.0000 1.0000
42.6000 110.0000 1.0000
42.7000 93.0000 1.0000
42.8000 105.0000 1.0000
42.9000 101.0000 1.0000
43.0000 84.0000 1.0000
43.1000 83.0000 1.0000
43.2000 102.0000 1.0000
43.3000 111.0000 1.0000
43.4000 92.0000 1.0000
43.5000 90.0000 1.0000
43.6000 96.0000 1.0000
43.7000 97.0000 1.0000
43.8000 91.0000 1.0000
43.9000 106.0000 1.0000
44.0000 91.0000 1.0000
44.1000 108.0000 1.0000
44.2000 96.0000 1.0000
44.3000 87.0000 1.0000
44.4000 88.0000 1.0000
44.5000 96.0000 1.0000
44.6000 82.0000 1.0000
44.7000 87.0000 1.0000
44.8000 105.0000 1.0000
44.9000 85.0000 1.0000
45.0000 101.0000 1.0000
45.1000 101.0000 1.0000
45.2000 93.0000 1.0000
45.3000 90.0000 1.0000
45.4000 89.0000 1.0000
45.5000 92.0000 1.0000
45.6000 89.0000 1.0000
45.7000 90.0000 1.0000
45.8000 92.0000 1.0000
45.9000 114.0000 1.0000
46.0000 85.0000 1.0000
46.1000 91.0000 1.0000
46.2000 106.0000 1.0000
46.3000 114.0000 1.0000
46.4000 117.0000 1.0000
46.5000 111.0000 1.0000
46.6000 135.0000 1.0000
46.7000 131.0000 1.0000
46.8000 176.0000 1.0000
46.9000 222.0000 1.0000
47.0000 436.0000 1.0000
47.1000 2485.0000 1.0000
47.2000 17791.0000 1.0000
47.3000 4725.0000 1.0000
47.4000 558.0000 1.0000
47.5000 261.0000 1.0000
47.6000 206.0000 1.0000
47.7000 143.0000 1.0000
47.8000 145.0000 1.0000
47.9000 118.0000 1.0000
48.0000 115.0000 1.0000
48.1000 126.0000 1.0000
48.2000 125.0000 1.0000
48.3000 95.0000 1.0000
48.4000 94.0000 1.0000
48.5000 89.0000 1.0000
48.6000 81.0000 1.0000
48.7000 84.0000 1.0000
48.8000 87.0000 1.0000
48.9000 81.0000 1.0000
49.0000 91.0000 1.0000
49.1000 83.0000 1.0000
49.2000 85.0000 1.0000
49.3000 94.0000 1.0000
49.4000 86.0000 1.0000
49.5000 74.0000 1.0000
49.6000 80.0000 1.0000
49.7000 66.0000 1.0000
49.8000 82.0000 1.0000
49.9000 81.0000 1.0000
50.0000 72.0000 1.0000
50.1000 67.0000 1.0000
50.2000 76.0000 1.0000
50.3000 70.0000 1.0000
50.4000 81.0000 1.0000
50.5000 75.0000 1.0000
50.6000 67.0000 1.0000
50.7000 72.0000 1.0000
50.8000 69.0000 1.0000
50.9000 82.0000 1.0000
51.0000 58.0000 1.0000
51.1000 73.0000 1.0000
51.2000 68.0000 1.0000
51.3000 70.0000 1.0000
51.4000 87.0000 1.0000
51.5000 88.0000 1.0000
51.6000 69.0000 1.0000
51.7000 79.0000 1.0000
51.8000 76.0000 1.0000
51.9000 75.0000 1.0000
52.0000 74.0000 1.0000
52.1000 81.0000 1.0000
52.2000 83.0000 1.0000
52.3000 85.0000 1.0000
52.4000 69.0000 1.0000
52.5000 84.0000 1.0000
52.6000 76.0000 1.0000
52.7000 75.0000 1.0000
52.8000 56.0000 1.0000
52.9000 82.0000 1.0000
53.0000 67.0000 1.0000
53.1000 81.0000 1.0000
53.2000 78.0000 1.0000
53.3000 82.0000 1.0000
53.4000 62.0000 1.0000
53.5000 65.0000 1.0000
53.6000 73.0000 1.0000
53.7000 74.0000 1.0000
53.8000 71.0000 1.0000
53.9000 69.0000 1.0000
54.0000 80.0000 1.0000
54.1000 59.0000 1.0000
54.2000 88.0000 1.0000
54.3000 93.0000 1.0000
54.4000 74.0000 1.0000
54.5000 74.0000 1.0000
54.6000 75.0000 1.0000
54.7000 70.0000 1.0000
54.8000 61.0000 1.0000
54.9000 81.0000 1.0000
55.0000 76.0000 1.0000
55.1000 80.0000 1.0000
55.2000 74.0000 1.0000
55.3000 71.0000 1.0000
55.4000 78.0000 1.0000
55.5000 93.0000 1.0000
55.6000 116.0000 1.0000
55.7000 178.0000 1.0000
55.8000 318.0000 1.0000
55.9000 984.0000 1.0000
56.0000 6868.0000 1.0000
56.1000 6754.0000 1.0000
56.2000 547.0000 1.0000
56.3000 203.0000 1.0000
56.4000 170.0000 1.0000
56.5000 102.0000 1.0000
56.6000 93.0000 1.0000
56.7000 93.0000 1.0000
56.8000 84.0000 1.0000
56.9000 76.0000 1.0000
57.0000 69.0000 1.0000
57.1000 74.0000 1.0000
57.2000 76.0000 1.0000
57.3000 80.0000 1.0000
57.4000 63.0000 1.0000
57.5000 64.0000 1.0000
57.6000 69.0000 1.0000
57.7000 74.0000 1.0000
57.8000 69.0000 1.0000
57.9000 49.0000 1.0000
58.0000 56.0000 1.0000
58.1000 63.0000 1.0000
58.2000 58.0000 1.0000
58.3000 55.0000 1.0000
58.4000 68.0000 1.0000
58.5000 62.0000 1.0000
58.6000 53.0000 1.0000
58.7000 46.0000 1.0000
58.8000 48.0000 1.0000
58.9000 58.0000 1.0000
59.0000 64.0000 1.0000
59.1000 53.0000 1.0000
59.2000 68.0000 1.0000
59.3000 48.0000 1.0000
59.4000 47.0000 1.0000
59.5000 44.0000 1.0000
59.6000 67.0000 1.0000
59.7000 51.0000 1.0000
59.8000 58.0000 1.0000
59.9000 58.0000 1.0000
60.0000 45.0000 1.0000
60.1000 57.0000 1.0000
60.2000 56.0000 1.0000
60.3000 57.0000 1.0000
60.4000 54.0000 1.0000
60.5000 34.0000 1.0000
60.6000 54.0000 1.0000
60.7000 48.0000 1.0000
60.8000 36.0000 1.0000
60.9000 53.0000 1.0000
61.0000 51.0000 1.0000
61.1000 49.0000 1.0000
61.2000 52.0000 1.0000
61.3000 47.0000 1.0000
61.4000 54.0000 1.0000
61.5000 40.0000 1.0000
61.6000 45.0000 1.0000
61.7000 42.0000 1.0000
61.8000 52.0000 1.0000
61.9000 45.0000 1.0000
62.0000 51.0000 1.0000
62.1000 47.0000 1.0000
62.2000 48.0000 1.0000
62.3000 55.0000 1.0000
62.4000 43.0000 1.0000
62.5000 53.0000 1.0000
62.6000 41.0000 1.0000
62.7000 46.0000 1.0000
62.8000 53.0000 1.0000
62.9000 52.0000 1.0000
63.0000 43.0000 1.0000
63.1000 47.0000 1.0000
63.2000 36.0000 1.0000
63.3000 57.0000 1.0000
63.4000 37.0000 1.0000
63.5000 51.0000 1.0000
63.6000 38.0000 1.0000
63.7000 48.0000 1.0000
63.8000 45.0000 1.0000
63.9000 41.0000 1.0000
64.0000 40.0000 1.0000
64.1000 42.0000 1.0000
64.2000 40.0000 1.0000
64.3000 49.0000 1.0000
64.4000 47.0000 1.0000
64.5000 39.0000 1.0000
64.6000 47.0000 1.0000
64.7000 43.0000 1.0000
64.8000 44.0000 1.0000
64.9000 31.0000 1.0000
65.0000 43.0000 1.0000
65.1000 43.0000 1.0000
65.2000 51.0000 1.0000
65.3000 52.0000 1.0000
65.4000 40.0000 1.0000
65.5000 42.0000 1.0000
65.6000 42.0000 1.0000
65.7000 45.0000 1.0000
65.8000 41.0000 1.0000
65.9000 45.0000 1.0000
66.0000 52.0000 1.0000
66.1000 50.0000 1.0000
66.2000 53.0000 1.0000
66.3000 46.0000 1.0000
66.4000 46.0000 1.0000
66.5000 44.0000 1.0000
66.6000 51.0000 1.0000
66.7000 44.0000 1.0000
66.8000 45.0000 1.0000
66.9000 41.0000 1.0000
67.0000 40.0000 1.0000
67.1000 45.0000 1.0000
67.2000 41.0000 1.0000
67.3000 42.0000 1.0000
67.4000 41.0000 1.0000
67.5000 45.0000 1.0000
67.6000 37.0000 1.0000
67.7000 42.0000 1.0000
67.8000 49.0000 1.0000
67.9000 42.0000 1.0000
68.0000 57.0000 1.0000
68.1000 42.0000 1.0000
68.2000 52.0000 1.0000
68.3000 59.0000 1.0000
68.4000 51.0000 1.0000
68.5000 48.0000 1.0000
68.6000 76.0000 1.0000
68.7000 86.0000 1.0000
68.8000 98.0000 1.0000
68.9000 278.0000 1.0000
69.0000 1426.0000 1.0000
69.1000 2269.0000 1.0000
69.2000 242.0000 1.0000
69.3000 101.0000 1.0000
69.4000 58.0000 1.0000
69.5000 72.0000 1.0000
69.6000 50.0000 1.0000
69.7000 58.0000 1.0000
69.8000 57.0000 1.0000
69.9000 52.0000 1.0000
70.0000 45.0000 1.0000
70.1000 51.0000 1.0000
70.2000 47.0000 1.0000
70.3000 42.0000 1.0000
70.4000 43.0000 1.0000
70.5000 58.0000 1.0000
70.6000 49.0000 1.0000
70.7000 40.0000 1.0000
70.8000 37.0000 1.0000
70.9000 44.0000 1.0000
71.0000 44.0000 1.0000
71.1000 36.0000 1.0000
71.2000 44.0000 1.0000
71.3000 40.0000 1.0000
71.4000 52.0000 1.0000
71.5000 32.0000 1.0000
71.6000 46.0000 1.0000
71.7000 54.0000 1.0000
71.8000 48.0000 1.0000
71.9000 47.0000 1.0000
72.0000 42.0000 1.0000
72.1000 34.0000 1.0000
72.2000 51.0000 1.0000
72.3000 43.0000 1.0000
72.4000 40.0000 1.0000
72.5000 53.0000 1.0000
72.6000 39.0000 1.0000
72.7000 26.0000 1.0000
72.8000 39.0000 1.0000
72.9000 37.0000 1.0000
73.0000 40.0000 1.0000
73.1000 53.0000 1.0000
73.2000 47.0000 1.0000
73.3000 49.0000 1.0000
73.4000 47.0000 1.0000
73.5000 38.0000 1.0000
73.6000 43.0000 1.0000
73.7000 37.0000 1.0000
73.8000 37.0000 1.0000
73.9000 38.0000 1.0000
74.0000 37.0000 1.0000
74.1000 46.0000 1.0000
74.2000 34.0000 1.0000
74.3000 54.0000 1.0000
74.4000 35.0000 1.0000
74.5000 52.0000 1.0000
74.6000 54.0000 1.0000
74.7000 45.0000 1.0000
74.8000 43.0000 1.0000
74.9000 44.0000 1.0000
75.0000 37.0000 1.0000
75.1000 65.0000 1.0000
75.2000 39.0000 1.0000
75.3000 47.0000 1.0000
75.4000 60.0000 1.0000
75.5000 51.0000 1.0000
75.6000 56.0000 1.0000
75.7000 70.0000 1.0000
75.8000 73.0000 1.0000
75.9000 85.0000 1.0000
76.0000 138.0000 1.0000
76.1000 257.0000 1.0000
76.2000 931.0000 1.0000
76.3000 5244.0000 1.0000
76.4000 862.0000 1.0000
76.5000 181.0000 1.0000
76.6000 101.0000 1.0000
76.7000 76.0000 1.0000
76.8000 78.0000 1.0000
76.9000 54.0000 1.0000
77.0000 42.0000 1.0000
77.1000 54.0000 1.0000
77.2000 61.0000 1.0000
77.3000 51.0000 1.0000
77.4000 43.0000 1.0000
77.5000 53.0000 1.0000
77.6000 36.0000 1.0000
77.7000 53.0000 1.0000
77.8000 37.0000 1.0000
77.9000 38.0000 1.0000
78.0000 43.0000 1.0000
78.1000 52.0000 1.0000
78.2000 47.0000 1.0000
78.3000 42.0000 1.0000
78.4000 46.0000 1.0000
78.5000 35.0000 1.0000
78.6000 42.0000 1.0000
78.7000 34.0000 1.0000
78.8000 40.0000 1.0000
78.9000 50.0000 1.0000
79.0000 34.0000 1.0000
79.1000 45.0000 1.0000
79.2000 38.0000 1.0000
79.3000 30.0000 1.0000
79.4000 40.0000 1.0000
79.5000 58.0000 1.0000
79.6000 42.0000 1.0000
79.7000 53.0000 1.0000
79.8000 52.0000 1.0000
79.9000 43.0000 1.0000
80.0000 43.0000 1.0000
80.1000 32.0000 1.0000
80.2000 53.0000 1.0000
80.3000 37.0000 1.0000
80.4000 52.0000 1.0000
80.5000 42.0000 1.0000
80.6000 46.0000 1.0000
80.7000 50.0000 1.0000
80.8000 41.0000 1.0000
80.9000 43.0000 1.0000
81.0000 40.0000 1.0000
81.1000 53.0000 1.0000
81.2000 39.0000 1.0000
81.3000 34.0000 1.0000
81.4000 42.0000 1.0000
81.5000 36.0000 1.0000
81.6000 51.0000 1.0000
81.7000 38.0000 1.0000
81.8000 43.0000 1.0000
81.9000 34.0000 1.0000
82.0000 50.0000 1.0000
82.1000 49.0000 1.0000
82.2000 46.0000 1.0000
82.3000 49.0000 1.0000
82.4000 39.0000 1.0000
82.5000 42.0000 1.0000
82.6000 39.0000 1.0000
82.7000 44.0000 1.0000
82.8000 38.0000 1.0000
82.9000 40.0000 1.0000
83.0000 48.0000 1.0000
83.1000 32.0000 1.0000
83.2000 43.0000 1.0000
83.3000 38.0000 1.0000
83.4000 42.0000 1.0000
83.5000 36.0000 1.0000
83.6000 46.0000 1.0000
83.7000 48.0000 1.0000
83.8000 45.0000 1.0000
83.9000 60.0000 1.0000
84.0000 51.0000 1.0000
84.1000 41.0000 1.0000
84.2000 41.0000 1.0000
84.3000 38.0000 1.0000
84.4000 42.0000 1.0000
84.5000 38.0000 1.0000
84.6000 49.0000 1.0000
84.7000 42.0000 1.0000
84.8000 43.0000 1.0000
84.9000 51.0000 1.0000
85.0000 41.0000 1.0000
85.1000 43.0000 1.0000
85.2000 52.0000 1.0000
85.3000 40.0000 1.0000
85.4000 45.0000 1.0000
85.5000 56.0000 1.0000
85.6000 35.0000 1.0000
85.7000 33.0000 1.0000
85.8000 43.0000 1.0000
85.9000 53.0000 1.0000
86.0000 48.0000 1.0000
86.1000 51.0000 1.0000
86.2000 44.0000 1.0000
86.3000 49.0000 1.0000
86.4000 41.0000 1.0000
86.5000 52.0000 1.0000
86.6000 41.0000 1.0000
86.7000 51.0000 1.0000
86.8000 52.0000 1.0000
86.9000 52.0000 1.0000
87.0000 54.0000 1.0000
87.1000 61.0000 1.0000
87.2000 57.0000 1.0000
87.3000 72.0000 1.0000
87.4000 66.0000 1.0000
87.5000 93.0000 1.0000
87.6000 135.0000 1.0000
87.7000 292.0000 1.0000
87.8000 671.0000 1.0000
87.9000 2702.0000 1.0000
88.0000 4958.0000 1.0000
88.1000 566.0000 1.0000
88.2000 195.0000 1.0000
88.3000 139.0000 1.0000
88.4000 89.0000 1.0000
88.5000 75.0000 1.0000
88.6000 56.0000 1.0000
88.7000 56.0000 1.0000
88.8000 54.0000 1.0000
88.9000 37.0000 1.0000
89.0000 63.0000 1.0000
89.1000 47.0000 1.0000
89.2000 65.0000 1.0000
89.3000 44.0000 1.0000
89.4000 55.0000 1.0000
89.5000 38.0000 1.0000
89.6000 45.0000 1.0000
89.7000 49.0000 1.0000
89.8000 50.0000 1.0000
89.9000 48.0000 1.0000
90.0000 46.0000 1.0000
90.1000 43.0000 1.0000
90.2000 43.0000 1.0000
90.3000 53.0000 1.0000
90.4000 43.0000 1.0000
90.5000 53.0000 1.0000
90.6000 52.0000 1.0000
90.7000 43.0000 1.0000
90.8000 45.0000 1.0000
90.9000 40.0000 1.0000
91.0000 34.0000 1.0000
91.1000 44.0000 1.0000
91.2000 50.0000 1.0000
91.3000 44.0000 1.0000
91.4000 50.0000 1.0000
91.5000 48.0000 1.0000
91.6000 43.0000 1.0000
91.7000 37.0000 1.0000
91.8000 40.0000 1.0000
91.9000 48.0000 1.0000
92.0000 37.0000 1.0000
92.1000 30.0000 1.0000
92.2000 42.0000 1.0000
92.3000 48.0000 1.0000
92.4000 47.0000 1.0000
92.5000 39.0000 1.0000
92.6000 45.0000 1.0000
92.7000 50.0000 1.0000
92.8000 43.0000 1.0000
92.9000 51.0000 1.0000
93.0000 46.0000 1.0000
93.1000 40.0000 1.0000
93.2000 44.0000 1.0000
93.3000 58.0000 1.0000
93.4000 54.0000 1.0000
93.5000 51.0000 1.0000
93.6000 45.0000 1.0000
93.7000 46.0000 1.0000
93.8000 62.0000 1.0000
93.9000 43.0000 1.0000
94.0000 55.0000 1.0000
94.1000 46.0000 1.0000
94.2000 59.0000 1.0000
94.3000 72.0000 1.0000
94.4000 70.0000 1.0000
94.5000 93.0000 1.0000
94.6000 173.0000 1.0000
94.7000 318.0000 1.0000
94.8000 1023.0000 1.0000
94.9000 3424.0000 1.0000
95.0000 632.0000 1.0000
95.1000 200.0000 1.0000
95.2000 99.0000 1.0000
95.3000 79.0000 1.0000
95.4000 60.0000 1.0000
95.5000 54.0000 1.0000
95.6000 52.0000 1.0000
95.7000 54.0000 1.0000
95.8000 49.0000 1.0000
95.9000 41.0000 1.0000
96.0000 49.0000 1.0000
96.1000 28.0000 1.0000
96.2000 41.0000 1.0000
96.3000 50.0000 1.0000
96.4000 42.0000 1.0000
96.5000 51.0000 1.0000
96.6000 40.0000 1.0000
96.7000 43.0000 1.0000
96.8000 39.0000 1.0000
96.9000 39.0000 1.0000
97.0000 46.0000 1.0000
97.1000 41.0000 1.0000
97.2000 33.0000 1.0000
97.3000 44.0000 1.0000
97.4000 34.0000 1.0000
97.5000 35.0000 1.0000
97.6000 32.0000 1.0000
97.7000 48.0000 1.0000
97.8000 46.0000 1.0000
97.9000 46.0000 1.0000
98.0000 50.0000 1.0000
98.1000 37.0000 1.0000
98.2000 35.0000 1.0000
98.3000 43.0000 1.0000
98.4000 32.0000 1.0000
98.5000 37.0000 1.0000
98.6000 37.0000 1.0000
98.7000 41.0000 1.0000
98.8000 33.0000 1.0000
98.9000 36.0000 1.0000
99.0000 41.0000 1.0000
99.1000 36.0000 1.0000
99.2000 44.0000 1.0000
99.3000 29.0000 1.0000
99.4000 50.0000 1.0000
99.5000 32.0000 1.0000
99.6000 40.0000 1.0000
99.7000 41.0000 1.0000
99.8000 47.0000 1.0000
99.9000 33.0000 1.0000
100.0000 46.0000 1.0000
100.1000 38.0000 1.0000
100.2000 45.0000 1.0000
100.3000 43.0000 1.0000
100.4000 39.0000 1.0000
100.5000 41.0000 1.0000
100.6000 44.0000 1.0000
100.7000 39.0000 1.0000
100.8000 44.0000 1.0000
100.9000 44.0000 1.0000
101.0000 34.0000 1.0000
101.1000 40.0000 1.0000
101.2000 32.0000 1.0000
101.3000 37.0000 1.0000
101.4000 44.0000 1.0000
101.5000 43.0000 1.0000
101.6000 51.0000 1.0000
101.7000 39.0000 1.0000
101.8000 39.0000 1.0000
101.9000 50.0000 1.0000
102.0000 34.0000 1.0000
102.1000 38.0000 1.0000
102.2000 38.0000 1.0000
102.3000 52.0000 1.0000
102.4000 42.0000 1.0000
102.5000 39.0000 1.0000
102.6000 39.0000 1.0000
102.7000 41.0000 1.0000
102.8000 45.0000 1.0000
102.9000 50.0000 1.0000
103.0000 38.0000 1.0000
103.1000 38.0000 1.0000
103.2000 42.0000 1.0000
103.3000 45.0000 1.0000
103.4000 50.0000 1.0000
103.5000 32.0000 1.0000
103.6000 43.0000 1.0000
103.7000 47.0000 1.0000
103.8000 45.0000 1.0000
103.9000 49.0000 1.0000
104.0000 44.0000 1.0000
104.1000 50.0000 1.0000
104.2000 39.0000 1.0000
104.3000 47.0000 1.0000
104.4000 47.0000 1.0000
104.5000 34.0000 1.0000
104.6000 40.0000 1.0000
104.7000 51.0000 1.0000
104.8000 40.0000 1.0000
104.9000 44.0000 1.0000
105.0000 47.0000 1.0000
105.1000 51.0000 1.0000
105.2000 45.0000 1.0000
105.3000 48.0000 1.0000
105.4000 63.0000 1.0000
105.5000 42.0000 1.0000
105.6000 44.0000 1.0000
105.7000 35.0000 1.0000
105.8000 56.0000 1.0000
105.9000 48.0000 1.0000
106.0000 55.0000 1.0000
106.1000 52.0000 1.0000
106.2000 71.0000 1.0000
106.3000 108.0000 1.0000
106.4000 187.0000 1.0000
106.5000 335.0000 1.0000
106.6000 1251.0000 1.0000
106.7000 1280.0000 1.0000
106.8000 261.0000 1.0000
106.9000 126.0000 1.0000
107.0000 104.0000 1.0000
107.1000 79.0000 1.0000
107.2000 58.0000 1.0000
107.3000 72.0000 1.0000
107.4000 59.0000 1.0000
107.5000 53.0000 1.0000
107.6000 52.0000 1.0000
107.7000 51.0000 1.0000
107.8000 48.0000 1.0000
107.9000 60.0000 1.0000
108.0000 49.0000 1.0000
108.1000 45.0000 1.0000
108.2000 43.0000 1.0000
108.3000 49.0000 1.0000
108.4000 41.0000 1.0000
108.5000 48.0000 1.0000
108.6000 47.0000 1.0000
108.7000 54.0000 1.0000
108.8000 52.0000 1.0000
108.9000 47.0000 1.0000
109.0000 38.0000 1.0000
109.1000 46.0000 1.0000
109.2000 56.0000 1.0000
109.3000 34.0000 1.0000
109.4000 46.0000 1.0000
109.5000 48.0000 1.0000
109.6000 41.0000 1.0000
109.7000 37.0000 1.0000
109.8000 34.0000 1.0000
109.9000 35.0000 1.0000
110.0000 43.0000 1.0000
110.1000 36.0000 1.0000
110.2000 41.0000 1.0000
110.3000 51.0000 1.0000
110.4000 48.0000 1.0000
110.5000 43.0000 1.0000
110.6000 59.0000 1.0000
110.7000 40.0000 1.0000
110.8000 45.0000 1.0000
110.9000 41.0000 1.0000
111.0000 31.0000 1.0000
111.1000 41.0000 1.0000
111.2000 49.0000 1.0000
111.3000 51.0000 1.0000
111.4000 45.0000 1.0000
111.5000 30.0000 1.0000
111.6000 41.0000 1.0000
111.7000 50.0000 1.0000
111.8000 49.0000 1.0000
111.9000 38.0000 1.0000
112.0000 43.0000 1.0000
112.1000 51.0000 1.0000
112.2000 62.0000 1.0000
112.3000 55.0000 1.0000
112.4000 50.0000 1.0000
112.5000 63.0000 1.0000
112.6000 43.0000 1.0000
112.7000 51.0000 1.0000
112.8000 64.0000 1.0000
112.9000 63.0000 1.0000
113.0000 53.0000 1.0000
113.1000 68.0000 1.0000
113.2000 64.0000 1.0000
113.3000 78.0000 1.0000
113.4000 97.0000 1.0000
113.5000 96.0000 1.0000
113.6000 133.0000 1.0000
113.7000 215.0000 1.0000
113.8000 335.0000 1.0000
113.9000 780.0000 1.0000
114.0000 2686.0000 1.0000
114.1000 1885.0000 1.0000
114.2000 462.0000 1.0000
114.3000 186.0000 1.0000
114.4000 123.0000 1.0000
114.5000 112.0000 1.0000
114.6000 73.0000 1.0000
114.7000 84.0000 1.0000
114.8000 73.0000 1.0000
114.9000 54.0000 1.0000
115.0000 62.0000 1.0000
115.1000 61.0000 1.0000
115.2000 48.0000 1.0000
115.3000 53.0000 1.0000
115.4000 63.0000 1.0000
115.5000 57.0000 1.0000
115.6000 47.0000 1.0000
115.7000 48.0000 1.0000
115.8000 42.0000 1.0000
115.9000 64.0000 1.0000
116.0000 48.0000 1.0000
116.1000 54.0000 1.0000
116.2000 50.0000 1.0000
116.3000 60.0000 1.0000
116.4000 48.0000 1.0000
116.5000 63.0000 1.0000
116.6000 50.0000 1.0000
116.7000 40.0000 1.0000
116.8000 52.0000 1.0000
116.9000 47.0000 1.0000
117.0000 41.0000 1.0000
117.1000 53.0000 1.0000
117.2000 48.0000 1.0000
117.3000 52.0000 1.0000
117.4000 44.0000 1.0000
117.5000 48.0000 1.0000
117.6000 43.0000 1.0000
117.7000 41.0000 1.0000
117.8000 55.0000 1.0000
117.9000 46.0000 1.0000
118.0000 53.0000 1.0000
118.1000 44.0000 1.0000
118.2000 49.0000 1.0000
118.3000 45.0000 1.0000
118.4000 51.0000 1.0000
118.5000 48.0000 1.0000
118.6000 45.0000 1.0000
118.7000 44.0000 1.0000
118.8000 33.0000 1.0000
118.9000 64.0000 1.0000
119.0000 51.0000 1.0000
119.1000 44.0000 1.0000
119.2000 54.0000 1.0000
119.3000 43.0000 1.0000
119.4000 47.0000 1.0000
119.5000 45.0000 1.0000
119.6000 55.0000 1.0000
119.7000 45.0000 1.0000
119.8000 48.0000 1.0000
119.9000 35.0000 1.0000
120.0000 43.0000 1.0000
120.1000 47.0000 1.0000
120.2000 50.0000 1.0000
120.3000 47.0000 1.0000
120.4000 37.0000 1.0000
120.5000 46.0000 1.0000
120.6000 49.0000 1.0000
120.7000 40.0000 1.0000
120.8000 42.0000 1.0000
120.9000 51.0000 1.0000
121.0000 63.0000 1.0000
121.1000 50.0000 1.0000
121.2000 51.0000 1.0000
121.3000 44.0000 1.0000
121.4000 46.0000 1.0000
121.5000 41.0000 1.0000
121.6000 45.0000 1.0000
121.7000 43.0000 1.0000
121.8000 40.0000 1.0000
121.9000 51.0000 1.0000
122.0000 44.0000 1.0000
122.1000 49.0000 1.0000
122.2000 54.0000 1.0000
122.3000 58.0000 1.0000
122.4000 47.0000 1.0000
122.5000 51.0000 1.0000
122.6000 56.0000 1.0000
[...]
83.8400 57.0000 1.0000
83.9000 46.0000 1.0000
83.9600 42.0000 1.0000
84.0200 49.0000 1.0000
84.0800 35.0000 1.0000
84.1400 52.0000 1.0000
84.2000 52.0000 1.0000
84.2600 45.0000 1.0000
84.3200 40.0000 1.0000
84.3800 48.0000 1.0000
84.4400 45.0000 1.0000
84.5000 41.0000 1.0000
84.5600 38.0000 1.0000
84.6200 58.0000 1.0000
84.6800 43.0000 1.0000
84.7400 42.0000 1.0000
84.8000 42.0000 1.0000
84.8600 45.0000 1.0000
84.9200 52.0000 1.0000
84.9800 46.0000 1.0000
85.0400 44.0000 1.0000
85.1000 45.0000 1.0000
85.1600 32.0000 1.0000
85.2200 39.0000 1.0000
85.2800 41.0000 1.0000
85.3400 60.0000 1.0000
85.4000 42.0000 1.0000
85.4600 48.0000 1.0000
85.5200 49.0000 1.0000
85.5800 52.0000 1.0000
85.6400 46.0000 1.0000
85.7000 49.0000 1.0000
85.7600 50.0000 1.0000
85.8200 46.0000 1.0000
85.8800 50.0000 1.0000
85.9400 49.0000 1.0000
86.0000 50.0000 1.0000
86.0600 43.0000 1.0000
86.1200 45.0000 1.0000
86.1800 43.0000 1.0000
86.2400 55.0000 1.0000
86.3000 43.0000 1.0000
86.3600 51.0000 1.0000
86.4200 43.0000 1.0000
86.4800 40.0000 1.0000
86.5400 52.0000 1.0000
86.6000 35.0000 1.0000
86.6600 49.0000 1.0000
86.7200 48.0000 1.0000
86.7800 52.0000 1.0000
86.8400 44.0000 1.0000
86.9000 62.0000 1.0000
86.9600 45.0000 1.0000
87.0200 52.0000 1.0000
87.0800 53.0000 1.0000
87.1400 65.0000 1.0000
87.2000 73.0000 1.0000
87.2600 78.0000 1.0000
87.3200 78.0000 1.0000
87.3800 92.0000 1.0000
87.4400 98.0000 1.0000
87.5000 91.0000 1.0000
87.5600 142.0000 1.0000
87.6200 155.0000 1.0000
87.6800 225.0000 1.0000
87.7400 362.0000 1.0000
87.8000 602.0000 1.0000
87.8600 1347.0000 1.0000
87.9200 3786.0000 1.0000
87.9800 6479.0000 1.0000
88.0400 1984.0000 1.0000
88.1000 626.0000 1.0000
88.1600 274.0000 1.0000
88.2200 195.0000 1.0000
88.2800 138.0000 1.0000
88.3400 95.0000 1.0000
88.4000 90.0000 1.0000
88.4600 92.0000 1.0000
88.5200 72.0000 1.0000
88.5800 92.0000 1.0000
88.6400 73.0000 1.0000
88.7000 76.0000 1.0000
88.7600 65.0000 1.0000
88.8200 68.0000 1.0000
88.8800 66.0000 1.0000
88.9400 67.0000 1.0000
89.0000 65.0000 1.0000
89.0600 51.0000 1.0000
89.1200 59.0000 1.0000
89.1800 51.0000 1.0000
89.2400 54.0000 1.0000
89.3000 54.0000 1.0000
89.3600 53.0000 1.0000
89.4200 56.0000 1.0000
89.4800 43.0000 1.0000
89.5400 44.0000 1.0000
89.6000 35.0000 1.0000
89.6600 47.0000 1.0000
89.7200 45.0000 1.0000
89.7800 54.0000 1.0000
89.8400 55.0000 1.0000
89.9000 44.0000 1.0000
89.9600 42.0000 1.0000
90.0000 46.0000 1.0000
*RAS_INT_END
*RAS_TEMPERATURE_START
20.0000 25.000
20.0600 25.000
20.1200 25.000
20.1800 25.000
20.2400 25.000
20.3000 25.000
20.3600 25.000
20.4200 25.000
20.4800 25.000
20.5400 25.000
20.6000 25.000
20.6600 25.000
20.7200 25.000
20.7800 25.000
20.8400 25.000
20.9000 25.000
20.9600 25.000
21.0200 25.000
21.0800 25.000
21.1400 25.000
21.2000 25.000
21.2600 25.000
21.3200 25.000
21.3800 25.000
21.4400 25.000
21.5000 25.000
21.5600 25.000
21.6200 25.000
21.6800 25.000
21.7400 25.000
21.8000 25.000
21.8600 25.000
21.9200 25.000
21.9800 25.000
22.0400 25.000
22.1000 25.000
22.1600 25.000
22.2200 25.000
22.2800 25.000
22.3400 25.000
22.4000 25.000
22.4600 25.000
22.5200 25.000
22.5800 25.000
22.6400 25.000
22.7000 25.000
22.7600 25.000
22.8200 25.000
22.8800 25.000
22.9400 25.000
23.0000 25.000
23.0600 25.000
23.1200 25.000
23.1800 25.000
23.2400 25.000
23.3000 25.000
23.3600 25.000
23.4200 25.000
23.4800 25.000
23.5400 25.000
23.6000 25.000
23.6600 25.000
23.7200 25.000
23.7800 25.000
23.8400 25.000
23.9000 25.000
23.9600 25.000
24.0200 25.000
24.0800 25.000
24.1400 25.000
24.2000 25.000
24.2600 25.000
24.3200 25.000
24.3800 25.000
24.4400 25.000
24.5000 25.000
24.5600 25.000
24.6200 25.000
24.6800 25.000
24.7400 25.000
24.8000 25.000
24.8600 25.000
24.9200 25.000
24.9800 25.000
25.0400 25.000
25.1000 25.000
25.1600 25.000
25.2200 25.000
25.2800 25.000
25.3400 25.000
25.4000 25.000
25.4600 25.000
25.5200 25.000
25.5800 25.000
25.6400 25.000
25.7000 25.000
25.7600 25.000
25.8200 25.000
25.8800 25.000
25.9400 25.000
26.0000 25.000
26.0600 25.000
26.1200 25.000
26.1800 25.000
26.2400 25.000
26.3000 25.000
26.3600 25.000
26.4200 25.000
26.4800 25.000
26.5400 25.000
26.6000 25.000
26.6600 25.000
26.7200 25.000
26.7800 25.000
26.8400 25.000
26.9000 25.000
26.9600 25.000
27.0200 25.000
27.0800 25.000
27.1400 25.000
27.2000 25.000
27.2600 25.000
27.3200 25.000
27.3800 25.000
27.4400 25.000
27.5000 25.000
27.5600 25.000
27.6200 25.000
27.6800 25.000
27.7400 25.000
27.8000 25.000
27.8600 25.000
27.9200 25.000
27.9800 25.000
28.0400 25.000
28.1000 25.000
28.1600 25.000
28.2200 25.000
28.2800 25.000
28.3400 25.000
28.4000 25.000
28.4600 25.000
28.5200 25.000
28.5800 25.000
28.6400 25.000
28.7000 25.000
28.7600 25.000
28.8200 25.000
28.8800 25.000
28.9400 25.000
29.0000 25.000
29.0600 25.000
29.1200 25.000
29.1800 25.000
29.2400 25.000
29.3000 25.000
29.3600 25.000
29.4200 25.000
29.4800 25.000
29.5400 25.000
29.6000 25.000
29.6600 25.000
29.7200 25.000
29.7800 25.000
29.8400 25.000
29.9000 25.000
29.9600 25.000
30.0200 25.000
30.0800 25.000
30.1400 25.000
30.2000 25.000
30.2600 25.000
30.3200 25.000
30.3800 25.000
30.4400 25.000
30.5000 25.000
30.5600 25.000
30.6200 25.000
30.6800 25.000
30.7400 25.000
30.8000 25.000
30.8600 25.000
30.9200 25.000
30.9800 25.000
31.0400 25.000
31.1000 25.000
31.1600 25.000
31.2200 25.000
31.2800 25.000
31.3400 25.000
31.4000 25.000
31.4600 25.000
31.5200 25.000
31.5800 25.000
31.6400 25.000
31.7000 25.000
31.7600 25.000
31.8200 25.000
31.8800 25.000
31.9400 25.000
32.0000 25.000
32.0600 25.000
32.1200 25.000
32.1800 25.000
32.2400 25.000
32.3000 25.000
32.3600 25.000
32.4200 25.000
32.4800 25.000
32.5400 25.000
32.6000 25.000
32.6600 25.000
32.7200 25.000
32.7800 25.000
32.8400 25.000
32.9000 25.000
32.9600 25.000
33.0200 25.000
33.0800 25.000
33.1400 25.000
33.2000 25.000
33.2600 25.000
33.3200 25.000
33.3800 25.000
33.4400 25.000
33.5000 25.000
33.5600 25.000
33.6200 25.000
33.6800 25.000
33.7400 25.000
33.8000 25.000
33.8600 25.000
33.9200 25.000
33.9800 25.000
34.0400 25.000
34.1000 25.000
34.1600 25.000
34.2200 25.000
34.2800 25.000
34.3400 25.000
34.4000 25.000
34.4600 25.000
34.5200 25.000
34.5800 25.000
34.6400 25.000
34.7000 25.000
34.7600 25.000
34.8200 25.000
34.8800 25.000
34.9400 25.000
35.0000 25.000
35.0600 25.000
35.1200 25.000
35.1800 25.000
35.2400 25.000
35.3000 25.000
35.3600 25.000
35.4200 25.000
35.4800 25.000
35.5400 25.000
35.6000 25.000
35.6600 25.000
35.7200 25.000
35.7800 25.000
35.8400 25.000
35.9000 25.000
35.9600 25.000
36.0200 25.000
36.0800 25.000
36.1400 25.000
36.2000 25.000
36.2600 25.000
36.3200 25.000
36.3800 25.000
36.4400 25.000
36.5000 25.000
36.5600 25.000
36.6200 25.000
36.6800 25.000
36.7400 25.000
36.8000 25.000
36.8600 25.000
36.9200 25.000
36.9800 25.000
37.0400 25.000
37.1000 25.000
37.1600 25.000
37.2200 25.000
37.2800 25.000
37.3400 25.000
37.4000 25.000
37.4600 25.000
37.5200 25.000
37.5800 25.000
37.6400 25.000
37.7000 25.000
37.7600 25.000
37.8200 25.000
37.8800 25.000
37.9400 25.000
38.0000 25.000
38.0600 25.000
38.1200 25.000
38.1800 25.000
38.2400 25.000
38.3000 25.000
38.3600 25.000
38.4200 25.000
38.4800 25.000
38.5400 25.000
38.6000 25.000
38.6600 25.000
38.7200 25.000
38.7800 25.000
38.8400 25.000
38.9000 25.000
38.9600 25.000
39.0200 25.000
39.0800 25.000
39.1400 25.000
39.2000 25.000
39.2600 25.000
39.3200 25.000
39.3800 25.000
39.4400 25.000
39.5000 25.000
39.5600 25.000
39.6200 25.000
39.6800 25.000
39.7400 25.000
39.8000 25.000
39.8600 25.000
39.9200 25.000
39.9800 25.000
40.0400 25.000
40.1000 25.000
40.1600 25.000
40.2200 25.000
40.2800 25.000
40.3400 25.000
40.4000 25.000
40.4600 25.000
40.5200 25.000
40.5800 25.000
40.6400 25.000
40.7000 25.000
40.7600 25.000
40.8200 25.000
40.8800 25.000
40.9400 25.000
41.0000 25.000
41.0600 25.000
41.1200 25.000
41.1800 25.000
41.2400 25.000
41.3000 25.000
41.3600 25.000
41.4200 25.000
41.4800 25.000
41.5400 25.000
41.6000 25.000
41.6600 25.000
41.7200 25.000
41.7800 25.000
41.8400 25.000
41.9000 25.000
41.9600 25.000
42.0200 25.000
42.0800 25.000
42.1400 25.000
42.2000 25.000
42.2600 25.000
42.3200 25.000
42.3800 25.000
42.4400 25.000
42.5000 25.000
42.5600 25.000
42.6200 25.000
42.6800 25.000
42.7400 25.000
42.8000 25.000
42.8600 25.000
42.9200 25.000
42.9800 25.000
43.0400 25.000
43.1000 25.000
43.1600 25.000
43.2200 25.000
43.2800 25.000
43.3400 25.000
43.4000 25.000
43.4600 25.000
43.5200 25.000
43.5800 25.000
43.6400 25.000
43.7000 25.000
43.7600 25.000
43.8200 25.000
43.8800 25.000
43.9400 25.000
44.0000 25.000
44.0600 25.000
44.1200 25.000
44.1800 25.000
44.2400 25.000
44.3000 25.000
44.3600 25.000
44.4200 25.000
44.4800 25.000
44.5400 25.000
44.6000 25.000
44.6600 25.000
44.7200 25.000
44.7800 25.000
44.8400 25.000
44.9000 25.000
44.9600 25.000
45.0200 25.000
45.0800 25.000
45.1400 25.000
45.2000 25.000
45.2600 25.000
45.3200 25.000
45.3800 25.000
45.4400 25.000
45.5000 25.000
45.5600 25.000
45.6200 25.000
45.6800 25.000
45.7400 25.000
45.8000 25.000
45.8600 25.000
45.9200 25.000
45.9800 25.000
46.0400 25.000
46.1000 25.000
46.1600 25.000
46.2200 25.000
46.2800 25.000
46.3400 25.000
46.4000 25.000
46.4600 25.000
46.5200 25.000
46.5800 25.000
46.6400 25.000
46.7000 25.000
46.7600 25.000
46.8200 25.000
46.8800 25.000
46.9400 25.000
47.0000 25.000
47.0600 25.000
47.1200 25.000
47.1800 25.000
47.2400 25.000
47.3000 25.000
47.3600 25.000
47.4200 25.000
47.4800 25.000
47.5400 25.000
47.6000 25.000
47.6600 25.000
47.7200 25.000
47.7800 25.000
47.8400 25.000
47.9000 25.000
47.9600 25.000
48.0200 25.000
48.0800 25.000
48.1400 25.000
48.2000 25.000
48.2600 25.000
48.3200 25.000
48.3800 25.000
48.4400 25.000
48.5000 25.000
48.5600 25.000
48.6200 25.000
48.6800 25.000
48.7400 25.000
48.8000 25.000
48.8600 25.000
48.9200 25.000
48.9800 25.000
49.0400 25.000
49.1000 25.000
49.1600 25.000
49.2200 25.000
49.2800 25.000
49.3400 25.000
49.4000 25.000
49.4600 25.000
49.5200 25.000
49.5800 25.000
49.6400 25.000
49.7000 25.000
49.7600 25.000
49.8200 25.000
49.8800 25.000
49.9400 25.000
50.0000 25.000
50.0600 25.000
50.1200 25.000
50.1800 25.000
50.2400 25.000
50.3000 25.000
50.3600 25.000
50.4200 25.000
50.4800 25.000
50.5400 25.000
50.6000 25.000
50.6600 25.000
50.7200 25.000
50.7800 25.000
50.8400 25.000
50.9000 25.000
50.9600 25.000
51.0200 25.000
51.0800 25.000
51.1400 25.000
51.2000 25.000
51.2600 25.000
51.3200 25.000
51.3800 25.000
51.4400 25.000
51.5000 25.000
51.5600 25.000
51.6200 25.000
51.6800 25.000
51.7400 25.000
51.8000 25.000
51.8600 25.000
51.9200 25.000
51.9800 25.000
52.0400 25.000
52.1000 25.000
52.1600 25.000
52.2200 25.000
52.2800 25.000
52.3400 25.000
52.4000 25.000
52.4600 25.000
52.5200 25.000
52.5800 25.000
52.6400 25.000
52.7000 25.000
52.7600 25.000
52.8200 25.000
52.8800 25.000
52.9400 25.000
53.0000 25.000
53.0600 25.000
53.1200 25.000
53.1800 25.000
53.2400 25.000
53.3000 25.000
53.3600 25.000
53.4200 25.000
53.4800 25.000
53.5400 25.000
53.6000 25.000
53.6600 25.000
53.7200 25.000
53.7800 25.000
53.8400 25.000
53.9000 25.000
53.9600 25.000
54.0200 25.000
54.0800 25.000
54.1400 25.000
54.2000 25.000
54.2600 25.000
54.3200 25.000
54.3800 25.000
54.4400 25.000
54.5000 25.000
54.5600 25.000
54.6200 25.000
54.6800 25.000
54.7400 25.000
54.8000 25.000
54.8600 25.000
54.9200 25.000
54.9800 25.000
55.0400 25.000
55.1000 25.000
55.1600 25.000
55.2200 25.000
55.2800 25.000
55.3400 25.000
55.4000 25.000
55.4600 25.000
55.5200 25.000
55.5800 25.000
55.6400 25.000
55.7000 25.000
55.7600 25.000
55.8200 25.000
55.8800 25.000
55.9400 25.000
56.0000 25.000
56.0600 25.000
56.1200 25.000
56.1800 25.000
56.2400 25.000
56.3000 25.000
56.3600 25.000
56.4200 25.000
56.4800 25.000
56.5400 25.000
56.6000 25.000
56.6600 25.000
56.7200 25.000
56.7800 25.000
56.8400 25.000
56.9000 25.000
56.9600 25.000
57.0200 25.000
57.0800 25.000
57.1400 25.000
57.2000 25.000
57.2600 25.000
57.3200 25.000
57.3800 25.000
57.4400 25.000
57.5000 25.000
57.5600 25.000
57.6200 25.000
57.6800 25.000
57.7400 25.000
57.8000 25.000
57.8600 25.000
57.9200 25.000
57.9800 25.000
58.0400 25.000
58.1000 25.000
58.1600 25.000
58.2200 25.000
58.2800 25.000
58.3400 25.000
58.4000 25.000
58.4600 25.000
58.5200 25.000
58.5800 25.000
58.6400 25.000
58.7000 25.000
58.7600 25.000
58.8200 25.000
58.8800 25.000
58.9400 25.000
59.0000 25.000
59.0600 25.000
59.1200 25.000
59.1800 25.000
59.2400 25.000
59.3000 25.000
59.3600 25.000
59.4200 25.000
59.4800 25.000
59.5400 25.000
59.6000 25.000
59.6600 25.000
59.7200 25.000
59.7800 25.000
59.8400 25.000
59.9000 25.000
59.9600 25.000
60.0200 25.000
60.0800 25.000
60.1400 25.000
60.2000 25.000
60.2600 25.000
60.3200 25.000
60.3800 25.000
60.4400 25.000
60.5000 25.000
60.5600 25.000
60.6200 25.000
60.6800 25.000
60.7400 25.000
60.8000 25.000
60.8600 25.000
60.9200 25.000
60.9800 25.000
61.0400 25.000
61.1000 25.000
61.1600 25.000
61.2200 25.000
61.2800 25.000
61.3400 25.000
61.4000 25.000
61.4600 25.000
61.5200 25.000
61.5800 25.000
61.6400 25.000
61.7000 25.000
61.7600 25.000
61.8200 25.000
61.8800 25.000
61.9400 25.000
62.0000 25.000
62.0600 25.000
62.1200 25.000
62.1800 25.000
62.2400 25.000
62.3000 25.000
62.3600 25.000
62.4200 25.000
62.4800 25.000
62.5400 25.000
62.6000 25.000
62.6600 25.000
62.7200 25.000
62.7800 25.000
62.8400 25.000
62.9000 25.000
62.9600 25.000
63.0200 25.000
63.0800 25.000
63.1400 25.000
63.2000 25.000
63.2600 25.000
63.3200 25.000
63.3800 25.000
63.4400 25.000
63.5000 25.000
63.5600 25.000
63.6200 25.000
63.6800 25.000
63.7400 25.000
63.8000 25.000
63.8600 25.000
63.9200 25.000
63.9800 25.000
64.0400 25.000
64.1000 25.000
64.1600 25.000
64.2200 25.000
64.2800 25.000
64.3400 25.000
64.4000 25.000
64.4600 25.000
64.5200 25.000
64.5800 25.000
64.6400 25.000
64.7000 25.000
64.7600 25.000
64.8200 25.000
64.8800 25.000
64.9400 25.000
65.0000 25.000
65.0600 25.000
65.1200 25.000
65.1800 25.000
65.2400 25.000
65.3000 25.000
65.3600 25.000
65.4200 25.000
65.4800 25.000
65.5400 25.000
65.6000 25.000
65.6600 25.000
65.7200 25.000
65.7800 25.000
65.8400 25.000
65.9000 25.000
65.9600 25.000
66.0200 25.000
66.0800 25.000
66.1400 25.000
66.2000 25.000
66.2600 25.000
66.3200 25.000
66.3800 25.000
66.4400 25.000
66.5000 25.000
66.5600 25.000
66.6200 25.000
66.6800 25.000
66.7400 25.000
66.8000 25.000
66.8600 25.000
66.9200 25.000
66.9800 25.000
67.0400 25.000
67.1000 25.000
67.1600 25.000
67.2200 25.000
67.2800 25.000
67.3400 25.000
67.4000 25.000
67.4600 25.000
67.5200 25.000
67.5800 25.000
67.6400 25.000
67.7000 25.000
67.7600 25.000
67.8200 25.000
67.8800 25.000
67.9400 25.000
68.0000 25.000
68.0600 25.000
68.1200 25.000
68.1800 25.000
68.2400 25.000
68.3000 25.000
68.3600 25.000
68.4200 25.000
68.4800 25.000
68.5400 25.000
68.6000 25.000
68.6600 25.000
68.7200 25.000
68.7800 25.000
68.8400 25.000
68.9000 25.000
68.9600 25.000
69.0200 25.000
69.0800 25.000
69.1400 25.000
69.2000 25.000
69.2600 25.000
69.3200 25.000
69.3800 25.000
69.4400 25.000
69.5000 25.000
69.5600 25.000
69.6200 25.000
69.6800 25.000
69.7400 25.000
69.8000 25.000
69.8600 25.000
69.9200 25.000
69.9800 25.000
70.0400 25.000
70.1000 25.000
70.1600 25.000
70.2200 25.000
70.2800 25.000
70.3400 25.000
70.4000 25.000
70.4600 25.000
70.5200 25.000
70.5800 25.000
70.6400 25.000
70.7000 25.000
70.7600 25.000
70.8200 25.000
70.8800 25.000
70.9400 25.000
71.0000 25.000
71.0600 25.000
71.1200 25.000
71.1800 25.000
71.2400 25.000
71.3000 25.000
71.3600 25.000
71.4200 25.000
71.4800 25.000
71.5400 25.000
71.6000 25.000
71.6600 25.000
71.7200 25.000
71.7800 25.000
71.8400 25.000
71.9000 25.000
71.9600 25.000
72.0200 25.000
72.0800 25.000
72.1400 25.000
72.2000 25.000
72.2600 25.000
72.3200 25.000
72.3800 25.000
72.4400 25.000
72.5000 25.000
72.5600 25.000
72.6200 25.000
72.6800 25.000
72.7400 25.000
72.8000 25.000
72.8600 25.000
72.9200 25.000
72.9800 25.000
73.0400 25.000
73.1000 25.000
73.1600 25.000
73.2200 25.000
73.2800 25.000
73.3400 25.000
73.4000 25.000
73.4600 25.000
73.5200 25.000
73.5800 25.000
73.6400 25.000
73.7000 25.000
73.7600 25.000
73.8200 25.000
73.8800 25.000
73.9400 25.000
74.0000 25.000
74.0600 25.000
74.1200 25.000
74.1800 25.000
74.2400 25.000
74.3000 25.000
74.3600 25.000
74.4200 25.000
74.4800 25.000
74.5400 25.000
74.6000 25.000
74.6600 25.000
74.7200 25.000
74.7800 25.000
74.8400 25.000
74.9000 25.000
74.9600 25.000
75.0200 25.000
75.0800 25.000
75.1400 25.000
75.2000 25.000
75.2600 25.000
75.3200 25.000
75.3800 25.000
75.4400 25.000
75.5000 25.000
75.5600 25.000
75.6200 25.000
75.6800 25.000
75.7400 25.000
75.8000 25.000
75.8600 25.000
75.9200 25.000
75.9800 25.000
76.0400 25.000
76.1000 25.000
76.1600 25.000
76.2200 25.000
76.2800 25.000
76.3400 25.000
76.4000 25.000
76.4600 25.000
76.5200 25.000
76.5800 25.000
76.6400 25.000
76.7000 25.000
76.7600 25.000
76.8200 25.000
76.8800 25.000
76.9400 25.000
77.0000 25.000
77.0600 25.000
77.1200 25.000
77.1800 25.000
77.2400 25.000
77.3000 25.000
77.3600 25.000
77.4200 25.000
77.4800 25.000
77.5400 25.000
77.6000 25.000
77.6600 25.000
77.7200 25.000
77.7800 25.000
77.8400 25.000
77.9000 25.000
77.9600 25.000
78.0200 25.000
78.0800 25.000
78.1400 25.000
78.2000 25.000
78.2600 25.000
78.3200 25.000
78.3800 25.000
78.4400 25.000
78.5000 25.000
78.5600 25.000
78.6200 25.000
78.6800 25.000
78.7400 25.000
78.8000 25.000
78.8600 25.000
78.9200 25.000
78.9800 25.000
79.0400 25.000
79.1000 25.000
79.1600 25.000
79.2200 25.000
79.2800 25.000
79.3400 25.000
79.4000 25.000
79.4600 25.000
79.5200 25.000
79.5800 25.000
79.6400 25.000
79.7000 25.000
79.7600 25.000
79.8200 25.000
79.8800 25.000
79.9400 25.000
80.0000 25.000
80.0600 25.000
80.1200 25.000
80.1800 25.000
80.2400 25.000
80.3000 25.000
80.3600 25.000
80.4200 25.000
80.4800 25.000
80.5400 25.000
80.6000 25.000
80.6600 25.000
80.7200 25.000
80.7800 25.000
80.8400 25.000
80.9000 25.000
80.9600 25.000
81.0200 25.000
81.0800 25.000
81.1400 25.000
81.2000 25.000
81.2600 25.000
81.3200 25.000
81.3800 25.000
81.4400 25.000
81.5000 25.000
81.5600 25.000
81.6200 25.000
81.6800 25.000
81.7400 25.000
81.8000 25.000
81.8600 25.000
81.9200 25.000
81.9800 25.000
82.0400 25.000
82.1000 25.000
82.1600 25.000
82.2200 25.000
82.2800 25.000
82.3400 25.000
82.4000 25.000
82.4600 25.000
82.5200 25.000
82.5800 25.000
82.6400 25.000
82.7000 25.000
82.7600 25.000
82.8200 25.000
82.8800 25.000
82.9400 25.000
83.0000 25.000
83.0600 25.000
83.1200 25.000
83.1800 25.000
83.2400 25.000
83.3000 25.000
83.3600 25.000
83.4200 25.000
83.4800 25.000
83.5400 25.000
83.6000 25.000
83.6600 25.000
83.7200 25.000
83.7800 25.000
83.8400 25.000
83.9000 25.000
83.9600 25.000
84.0200 25.000
84.0800 25.000
84.1400 25.000
84.2000 25.000
84.2600 25.000
84.3200 25.000
84.3800 25.000
84.4400 25.000
84.5000 25.000
84.5600 25.000
84.6200 25.000
84.6800 25.000
84.7400 25.000
84.8000 25.000
84.8600 25.000
84.9200 25.000
84.9800 25.000
85.0400 25.000
85.1000 25.000
85.1600 25.000
85.2200 25.000
85.2800 25.000
85.3400 25.000
85.4000 25.000
85.4600 25.000
85.5200 25.000
85.5800 25.000
85.6400 25.000
85.7000 25.000
85.7600 25.000
85.8200 25.000
85.8800 25.000
85.9400 25.000
86.0000 25.000
86.0600 25.000
86.1200 25.000
86.1800 25.000
86.2400 25.000
86.3000 25.000
86.3600 25.000
86.4200 25.000
86.4800 25.000
86.5400 25.000
86.6000 25.000
86.6600 25.000
86.7200 25.000
86.7800 25.000
86.8400 25.000
86.9000 25.000
86.9600 25.000
87.0200 25.000
87.0800 25.000
87.1400 25.000
87.2000 25.000
87.2600 25.000
87.3200 25.000
87.3800 25.000
87.4400 25.000
87.5000 25.000
87.5600 25.000
87.6200 25.000
87.6800 25.000
87.7400 25.000
87.8000 25.000
87.8600 25.000
87.9200 25.000
87.9800 25.000
88.0400 25.000
88.1000 25.000
88.1600 25.000
88.2200 25.000
88.2800 25.000
88.3400 25.000
88.4000 25.000
88.4600 25.000
88.5200 25.000
88.5800 25.000
88.6400 25.000
88.7000 25.000
88.7600 25.000
88.8200 25.000
88.8800 25.000
88.9400 25.000
89.0000 25.000
89.0600 25.000
89.1200 25.000
89.1800 25.000
89.2400 25.000
89.3000 25.000
89.3600 25.000
89.4200 25.000
89.4800 25.000
89.5400 25.000
89.6000 25.000
89.6600 25.000
89.7200 25.000
89.7800 25.000
89.8400 25.000
89.9000 25.000
89.9600 25.000
90.0000 25.000
*RAS_TEMPERATURE_END
*RAS_DATA_END